Workbook

Sheet Start Here
B1: Bulk Purchase Upload
B2: Purchase Orders and Goods Receipt from one Excel file
B4: How it works
B5: 1. List your vendors | C5: On the Vendors sheet, once: the vendor's name and State. City, GSTIN, phone and email only if you have them.
B6: 2. Fill the Purchase sheet | C6: One row for each design in each colour / size you are ordering. Rows with the same PO Ref become one Purchase Order. New designs are created automatically; you do not need SKU codes or barcodes.
B7: 3. Send the file to us | C7: With the photos, if any. We upload it in Wholeops. Every PO is created in one click, and you can see and print them in the app.
B8: 4. When the parcel and bill arrive | C8: Fill the green columns on the Purchase sheet (Vendor Invoice No, and Received Qty only if it is short or extra) and add the bill on the Bills sheet. Send the same file again. The goods are received into stock, barcodes are issued and stickers are ready to print.
B9: Goods already here? | C9: Fill everything, green columns and Bills sheet included, in one go.
B11: Rules
B12: • One row = one design in one colour / size. Rows with the same Design No are one design in different colours or sizes: use any label you like (1, 2, 3 or EI001) - it only groups the rows of this file, and Wholeops gives every design its own number. Leave it blank and the row is a design of its own. To reorder a design already in Wholeops, write its Wholeops design number (e.g. D00010).
B13: • Qty is in pieces you sell. A pair of earrings = 1. A set = 1.
B14: • Purchase Rate is per piece, including GST, as on the vendor's bill. MRP is the price printed on the sticker.
B15: • Photos: write each photo's file name in the Photo column - any name you like (several: a.jpg, b.jpg) - and send the photos with this file. Send JPG photos (PNG, WebP or GIF also work), up to 10 MB each. Each photo goes to its row's item and is renamed after the item's Wholeops number; the first photo of a design also goes to the design.
B16: • HSN Code: pick it from the list (the Codes sheet says which one fits). Artificial / fashion jewellery is 7117; real gold or silver is 7113. GST fills itself: all jewellery is 3%.
B17: • Vendor GSTIN is optional. The vendor's State is enough to charge the right GST (same state as your store: CGST + SGST; another state: IGST). Only vendors used on the Purchase sheet are created; sample rows left on the Vendors sheet are ignored.
B18: • Leave an optional box blank when it does not apply. Do not write NA or -.
B19: • A new product type, category, style, colour, polish, size or stone can simply be typed: Wholeops creates it on upload (add it to the Lists sheet so the drop-down offers it next time). A new store must be set up in Wholeops first: tell us.
B20: • A required box turns red while it is empty. Column A (Check) must say OK on every row of the Vendors, Purchase and Bills sheets before you send the file.
B21: • Do not rename, move or delete the column headers, row 2 or the sheets. Grey columns fill themselves.
B22: • Sending the file again is safe: a PO already created (same PO Ref and vendor) is not created twice.
B24: Colours
C25: You fill it: required
C26: You fill it: optional
C27: You fill it when the goods arrive
C28: Automatic: do not type here
C29: Required but still empty: fill it
B31: Your file right now
B32: Vendors | C32: =SUMPRODUCT(--(LEN(Vendors!$A$3:$A$202)>0)) -> 7
B33: Vendors to fix | C33: =SUMPRODUCT((LEN(Vendors!$A$3:$A$202)>0)*(Vendors!$A$3:$A$202<>"OK")) -> 0
B34: Purchase rows | C34: =SUMPRODUCT(--(LEN(Purchase!$A$3:$A$1002)>0)) -> 0
B35: Rows to fix | C35: =SUMPRODUCT((LEN(Purchase!$A$3:$A$1002)>0)*(Purchase!$A$3:$A$1002<>"OK")) -> 0
B36: Total Qty | C36: =SUM(Purchase!$Q$3:$Q$1002) -> 0
B37: Total Amount ₹ | C37: =SUM(Purchase!$T$3:$T$1002) -> 0
B38: Bills | C38: =SUMPRODUCT(--(LEN(Bills!$A$3:$A$302)>0)) -> 0
B39: Bills to fix | C39: =SUMPRODUCT((LEN(Bills!$A$3:$A$302)>0)*(Bills!$A$3:$A$302<>"OK")) -> 0
B40: Status | C40: =IF(C34=0,"Not started",IF(C33+C35+C39=0,"Ready to send","Fix the rows marked red in column A")) -> Not started
B42: Column guide (Purchase sheet)
B43: Column | C43: Required? | D43: What to write | E43: Example
B44: PO Ref | C44: Yes | D44: Any name for the order. All rows with the same PO Ref and vendor become one PO. | E44: SIY-OCT-01
B45: Vendor | C45: Yes | D45: Who you buy from. Pick from the list; the list is your Vendors sheet. | E45: Siyyona
...

Sheet Vendors
A1: Check | B1: Vendor Name * | C1: State * | D1: City | E1: GSTIN | F1: Phone | G1: Email
A2: # Automatic: says OK, or what to fix | B2: Required. As you want it on the PO | C2: Required. Where the vendor is. Decides CGST + SGST or IGST | D2: Optional | E2: Optional. Leave blank if you do not know it | F2: Optional | G2: Optional. POs can be emailed here
A3: =IF(COUNTA(B3:G3)=0,"",IF((IF(B3="","Vendor Name, ","")&IF(C3="","State, ",""))<>"","Missing: "&LEFT(IF(B3="","Vendor Name, ","")&IF(C3="","State, ",""),LEN(IF(B3="","Vendor Name, ","")&IF(C3="","State, ",""))-2),IF(COUNTIF($B$3:$B$202,B3)>1,"Vendor "&B3&" is listed twice",IF(ISNA(MATCH(C3,Codes!$E$2:$E$37,0)),"Pick the State from the list",IF(E3="","OK",IF(LEN(TRIM(E3))<>15,"GSTIN must be 15 characters - or leave it blank",IF(LEFT(TRIM(E3),2)<>INDEX(Codes!$F$2:$F$37,MATCH(C3,Codes!$E$2:$E$37,0)),"GSTIN starts with "&LEFT(TRIM(E3),2)&" but "&C3&" is "&INDEX(Codes!$F$2:$F$37,MATCH(C3,Codes!$E$2:$E$37,0)),"OK"))))))) -> OK | B3: Siyyona | C3: Maharashtra | D3: Mumbai
A4: =IF(COUNTA(B4:G4)=0,"",IF((IF(B4="","Vendor Name, ","")&IF(C4="","State, ",""))<>"","Missing: "&LEFT(IF(B4="","Vendor Name, ","")&IF(C4="","State, ",""),LEN(IF(B4="","Vendor Name, ","")&IF(C4="","State, ",""))-2),IF(COUNTIF($B$3:$B$202,B4)>1,"Vendor "&B4&" is listed twice",IF(ISNA(MATCH(C4,Codes!$E$2:$E$37,0)),"Pick the State from the list",IF(E4="","OK",IF(LEN(TRIM(E4))<>15,"GSTIN must be 15 characters - or leave it blank",IF(LEFT(TRIM(E4),2)<>INDEX(Codes!$F$2:$F$37,MATCH(C4,Codes!$E$2:$E$37,0)),"GSTIN starts with "&LEFT(TRIM(E4),2)&" but "&C4&" is "&INDEX(Codes!$F$2:$F$37,MATCH(C4,Codes!$E$2:$E$37,0)),"OK"))))))) -> OK | B4: Thofa | C4: Maharashtra | D4: Mumbai
A5: =IF(COUNTA(B5:G5)=0,"",IF((IF(B5="","Vendor Name, ","")&IF(C5="","State, ",""))<>"","Missing: "&LEFT(IF(B5="","Vendor Name, ","")&IF(C5="","State, ",""),LEN(IF(B5="","Vendor Name, ","")&IF(C5="","State, ",""))-2),IF(COUNTIF($B$3:$B$202,B5)>1,"Vendor "&B5&" is listed twice",IF(ISNA(MATCH(C5,Codes!$E$2:$E$37,0)),"Pick the State from the list",IF(E5="","OK",IF(LEN(TRIM(E5))<>15,"GSTIN must be 15 characters - or leave it blank",IF(LEFT(TRIM(E5),2)<>INDEX(Codes!$F$2:$F$37,MATCH(C5,Codes!$E$2:$E$37,0)),"GSTIN starts with "&LEFT(TRIM(E5),2)&" but "&C5&" is "&INDEX(Codes!$F$2:$F$37,MATCH(C5,Codes!$E$2:$E$37,0)),"OK"))))))) -> OK | B5: YJ NX | C5: Maharashtra | D5: Mumbai
A6: =IF(COUNTA(B6:G6)=0,"",IF((IF(B6="","Vendor Name, ","")&IF(C6="","State, ",""))<>"","Missing: "&LEFT(IF(B6="","Vendor Name, ","")&IF(C6="","State, ",""),LEN(IF(B6="","Vendor Name, ","")&IF(C6="","State, ",""))-2),IF(COUNTIF($B$3:$B$202,B6)>1,"Vendor "&B6&" is listed twice",IF(ISNA(MATCH(C6,Codes!$E$2:$E$37,0)),"Pick the State from the list",IF(E6="","OK",IF(LEN(TRIM(E6))<>15,"GSTIN must be 15 characters - or leave it blank",IF(LEFT(TRIM(E6),2)<>INDEX(Codes!$F$2:$F$37,MATCH(C6,Codes!$E$2:$E$37,0)),"GSTIN starts with "&LEFT(TRIM(E6),2)&" but "&C6&" is "&INDEX(Codes!$F$2:$F$37,MATCH(C6,Codes!$E$2:$E$37,0)),"OK"))))))) -> OK | B6: Shwetha | C6: Maharashtra | D6: Mumbai
A7: =IF(COUNTA(B7:G7)=0,"",IF((IF(B7="","Vendor Name, ","")&IF(C7="","State, ",""))<>"","Missing: "&LEFT(IF(B7="","Vendor Name, ","")&IF(C7="","State, ",""),LEN(IF(B7="","Vendor Name, ","")&IF(C7="","State, ",""))-2),IF(COUNTIF($B$3:$B$202,B7)>1,"Vendor "&B7&" is listed twice",IF(ISNA(MATCH(C7,Codes!$E$2:$E$37,0)),"Pick the State from the list",IF(E7="","OK",IF(LEN(TRIM(E7))<>15,"GSTIN must be 15 characters - or leave it blank",IF(LEFT(TRIM(E7),2)<>INDEX(Codes!$F$2:$F$37,MATCH(C7,Codes!$E$2:$E$37,0)),"GSTIN starts with "&LEFT(TRIM(E7),2)&" but "&C7&" is "&INDEX(Codes!$F$2:$F$37,MATCH(C7,Codes!$E$2:$E$37,0)),"OK"))))))) -> OK | B7: Piccasso | C7: Maharashtra | D7: Mumbai
A8: =IF(COUNTA(B8:G8)=0,"",IF((IF(B8="","Vendor Name, ","")&IF(C8="","State, ",""))<>"","Missing: "&LEFT(IF(B8="","Vendor Name, ","")&IF(C8="","State, ",""),LEN(IF(B8="","Vendor Name, ","")&IF(C8="","State, ",""))-2),IF(COUNTIF($B$3:$B$202,B8)>1,"Vendor "&B8&" is listed twice",IF(ISNA(MATCH(C8,Codes!$E$2:$E$37,0)),"Pick the State from the list",IF(E8="","OK",IF(LEN(TRIM(E8))<>15,"GSTIN must be 15 characters - or leave it blank",IF(LEFT(TRIM(E8),2)<>INDEX(Codes!$F$2:$F$37,MATCH(C8,Codes!$E$2:$E$37,0)),"GSTIN starts with "&LEFT(TRIM(E8),2)&" but "&C8&" is "&INDEX(Codes!$F$2:$F$37,MATCH(C8,Codes!$E$2:$E$37,0)),"OK"))))))) -> OK | B8: Pashwa | C8: Maharashtra | D8: Mumbai
A9: =IF(COUNTA(B9:G9)=0,"",IF((IF(B9="","Vendor Name, ","")&IF(C9="","State, ",""))<>"","Missing: "&LEFT(IF(B9="","Vendor Name, ","")&IF(C9="","State, ",""),LEN(IF(B9="","Vendor Name, ","")&IF(C9="","State, ",""))-2),IF(COUNTIF($B$3:$B$202,B9)>1,"Vendor "&B9&" is listed twice",IF(ISNA(MATCH(C9,Codes!$E$2:$E$37,0)),"Pick the State from the list",IF(E9="","OK",IF(LEN(TRIM(E9))<>15,"GSTIN must be 15 characters - or leave it blank",IF(LEFT(TRIM(E9),2)<>INDEX(Codes!$F$2:$F$37,MATCH(C9,Codes!$E$2:$E$37,0)),"GSTIN starts with "&LEFT(TRIM(E9),2)&" but "&C9&" is "&INDEX(Codes!$F$2:$F$37,MATCH(C9,Codes!$E$2:$E$37,0)),"OK"))))))) -> OK | B9: Bittu | C9: Maharashtra | D9: Mumbai
A10: =IF(COUNTA(B10:G10)=0,"",IF((IF(B10="","Vendor Name, ","")&IF(C10="","State, ",""))<>"","Missing: "&LEFT(IF(B10="","Vendor Name, ","")&IF(C10="","State, ",""),LEN(IF(B10="","Vendor Name, ","")&IF(C10="","State, ",""))-2),IF(COUNTIF($B$3:$B$202,B10)>1,"Vendor "&B10&" is listed twice",IF(ISNA(MATCH(C10,Codes!$E$2:$E$37,0)),"Pick the State from the list",IF(E10="","OK",IF(LEN(TRIM(E10))<>15,"GSTIN must be 15 characters - or leave it blank",IF(LEFT(TRIM(E10),2)<>INDEX(Codes!$F$2:$F$37,MATCH(C10,Codes!$E$2:$E$37,0)),"GSTIN starts with "&LEFT(TRIM(E10),2)&" but "&C10&" is "&INDEX(Codes!$F$2:$F$37,MATCH(C10,Codes!$E$2:$E$37,0)),"OK")))))))
A11: =IF(COUNTA(B11:G11)=0,"",IF((IF(B11="","Vendor Name, ","")&IF(C11="","State, ",""))<>"","Missing: "&LEFT(IF(B11="","Vendor Name, ","")&IF(C11="","State, ",""),LEN(IF(B11="","Vendor Name, ","")&IF(C11="","State, ",""))-2),IF(COUNTIF($B$3:$B$202,B11)>1,"Vendor "&B11&" is listed twice",IF(ISNA(MATCH(C11,Codes!$E$2:$E$37,0)),"Pick the State from the list",IF(E11="","OK",IF(LEN(TRIM(E11))<>15,"GSTIN must be 15 characters - or leave it blank",IF(LEFT(TRIM(E11),2)<>INDEX(Codes!$F$2:$F$37,MATCH(C11,Codes!$E$2:$E$37,0)),"GSTIN starts with "&LEFT(TRIM(E11),2)&" but "&C11&" is "&INDEX(Codes!$F$2:$F$37,MATCH(C11,Codes!$E$2:$E$37,0)),"OK")))))))
A12: =IF(COUNTA(B12:G12)=0,"",IF((IF(B12="","Vendor Name, ","")&IF(C12="","State, ",""))<>"","Missing: "&LEFT(IF(B12="","Vendor Name, ","")&IF(C12="","State, ",""),LEN(IF(B12="","Vendor Name, ","")&IF(C12="","State, ",""))-2),IF(COUNTIF($B$3:$B$202,B12)>1,"Vendor "&B12&" is listed twice",IF(ISNA(MATCH(C12,Codes!$E$2:$E$37,0)),"Pick the State from the list",IF(E12="","OK",IF(LEN(TRIM(E12))<>15,"GSTIN must be 15 characters - or leave it blank",IF(LEFT(TRIM(E12),2)<>INDEX(Codes!$F$2:$F$37,MATCH(C12,Codes!$E$2:$E$37,0)),"GSTIN starts with "&LEFT(TRIM(E12),2)&" but "&C12&" is "&INDEX(Codes!$F$2:$F$37,MATCH(C12,Codes!$E$2:$E$37,0)),"OK")))))))
A13: =IF(COUNTA(B13:G13)=0,"",IF((IF(B13="","Vendor Name, ","")&IF(C13="","State, ",""))<>"","Missing: "&LEFT(IF(B13="","Vendor Name, ","")&IF(C13="","State, ",""),LEN(IF(B13="","Vendor Name, ","")&IF(C13="","State, ",""))-2),IF(COUNTIF($B$3:$B$202,B13)>1,"Vendor "&B13&" is listed twice",IF(ISNA(MATCH(C13,Codes!$E$2:$E$37,0)),"Pick the State from the list",IF(E13="","OK",IF(LEN(TRIM(E13))<>15,"GSTIN must be 15 characters - or leave it blank",IF(LEFT(TRIM(E13),2)<>INDEX(Codes!$F$2:$F$37,MATCH(C13,Codes!$E$2:$E$37,0)),"GSTIN starts with "&LEFT(TRIM(E13),2)&" but "&C13&" is "&INDEX(Codes!$F$2:$F$37,MATCH(C13,Codes!$E$2:$E$37,0)),"OK")))))))
A14: =IF(COUNTA(B14:G14)=0,"",IF((IF(B14="","Vendor Name, ","")&IF(C14="","State, ",""))<>"","Missing: "&LEFT(IF(B14="","Vendor Name, ","")&IF(C14="","State, ",""),LEN(IF(B14="","Vendor Name, ","")&IF(C14="","State, ",""))-2),IF(COUNTIF($B$3:$B$202,B14)>1,"Vendor "&B14&" is listed twice",IF(ISNA(MATCH(C14,Codes!$E$2:$E$37,0)),"Pick the State from the list",IF(E14="","OK",IF(LEN(TRIM(E14))<>15,"GSTIN must be 15 characters - or leave it blank",IF(LEFT(TRIM(E14),2)<>INDEX(Codes!$F$2:$F$37,MATCH(C14,Codes!$E$2:$E$37,0)),"GSTIN starts with "&LEFT(TRIM(E14),2)&" but "&C14&" is "&INDEX(Codes!$F$2:$F$37,MATCH(C14,Codes!$E$2:$E$37,0)),"OK")))))))
A15: =IF(COUNTA(B15:G15)=0,"",IF((IF(B15="","Vendor Name, ","")&IF(C15="","State, ",""))<>"","Missing: "&LEFT(IF(B15="","Vendor Name, ","")&IF(C15="","State, ",""),LEN(IF(B15="","Vendor Name, ","")&IF(C15="","State, ",""))-2),IF(COUNTIF($B$3:$B$202,B15)>1,"Vendor "&B15&" is listed twice",IF(ISNA(MATCH(C15,Codes!$E$2:$E$37,0)),"Pick the State from the list",IF(E15="","OK",IF(LEN(TRIM(E15))<>15,"GSTIN must be 15 characters - or leave it blank",IF(LEFT(TRIM(E15),2)<>INDEX(Codes!$F$2:$F$37,MATCH(C15,Codes!$E$2:$E$37,0)),"GSTIN starts with "&LEFT(TRIM(E15),2)&" but "&C15&" is "&INDEX(Codes!$F$2:$F$37,MATCH(C15,Codes!$E$2:$E$37,0)),"OK")))))))
A16: =IF(COUNTA(B16:G16)=0,"",IF((IF(B16="","Vendor Name, ","")&IF(C16="","State, ",""))<>"","Missing: "&LEFT(IF(B16="","Vendor Name, ","")&IF(C16="","State, ",""),LEN(IF(B16="","Vendor Name, ","")&IF(C16="","State, ",""))-2),IF(COUNTIF($B$3:$B$202,B16)>1,"Vendor "&B16&" is listed twice",IF(ISNA(MATCH(C16,Codes!$E$2:$E$37,0)),"Pick the State from the list",IF(E16="","OK",IF(LEN(TRIM(E16))<>15,"GSTIN must be 15 characters - or leave it blank",IF(LEFT(TRIM(E16),2)<>INDEX(Codes!$F$2:$F$37,MATCH(C16,Codes!$E$2:$E$37,0)),"GSTIN starts with "&LEFT(TRIM(E16),2)&" but "&C16&" is "&INDEX(Codes!$F$2:$F$37,MATCH(C16,Codes!$E$2:$E$37,0)),"OK")))))))
A17: =IF(COUNTA(B17:G17)=0,"",IF((IF(B17="","Vendor Name, ","")&IF(C17="","State, ",""))<>"","Missing: "&LEFT(IF(B17="","Vendor Name, ","")&IF(C17="","State, ",""),LEN(IF(B17="","Vendor Name, ","")&IF(C17="","State, ",""))-2),IF(COUNTIF($B$3:$B$202,B17)>1,"Vendor "&B17&" is listed twice",IF(ISNA(MATCH(C17,Codes!$E$2:$E$37,0)),"Pick the State from the list",IF(E17="","OK",IF(LEN(TRIM(E17))<>15,"GSTIN must be 15 characters - or leave it blank",IF(LEFT(TRIM(E17),2)<>INDEX(Codes!$F$2:$F$37,MATCH(C17,Codes!$E$2:$E$37,0)),"GSTIN starts with "&LEFT(TRIM(E17),2)&" but "&C17&" is "&INDEX(Codes!$F$2:$F$37,MATCH(C17,Codes!$E$2:$E$37,0)),"OK")))))))
A18: =IF(COUNTA(B18:G18)=0,"",IF((IF(B18="","Vendor Name, ","")&IF(C18="","State, ",""))<>"","Missing: "&LEFT(IF(B18="","Vendor Name, ","")&IF(C18="","State, ",""),LEN(IF(B18="","Vendor Name, ","")&IF(C18="","State, ",""))-2),IF(COUNTIF($B$3:$B$202,B18)>1,"Vendor "&B18&" is listed twice",IF(ISNA(MATCH(C18,Codes!$E$2:$E$37,0)),"Pick the State from the list",IF(E18="","OK",IF(LEN(TRIM(E18))<>15,"GSTIN must be 15 characters - or leave it blank",IF(LEFT(TRIM(E18),2)<>INDEX(Codes!$F$2:$F$37,MATCH(C18,Codes!$E$2:$E$37,0)),"GSTIN starts with "&LEFT(TRIM(E18),2)&" but "&C18&" is "&INDEX(Codes!$F$2:$F$37,MATCH(C18,Codes!$E$2:$E$37,0)),"OK")))))))
A19: =IF(COUNTA(B19:G19)=0,"",IF((IF(B19="","Vendor Name, ","")&IF(C19="","State, ",""))<>"","Missing: "&LEFT(IF(B19="","Vendor Name, ","")&IF(C19="","State, ",""),LEN(IF(B19="","Vendor Name, ","")&IF(C19="","State, ",""))-2),IF(COUNTIF($B$3:$B$202,B19)>1,"Vendor "&B19&" is listed twice",IF(ISNA(MATCH(C19,Codes!$E$2:$E$37,0)),"Pick the State from the list",IF(E19="","OK",IF(LEN(TRIM(E19))<>15,"GSTIN must be 15 characters - or leave it blank",IF(LEFT(TRIM(E19),2)<>INDEX(Codes!$F$2:$F$37,MATCH(C19,Codes!$E$2:$E$37,0)),"GSTIN starts with "&LEFT(TRIM(E19),2)&" but "&C19&" is "&INDEX(Codes!$F$2:$F$37,MATCH(C19,Codes!$E$2:$E$37,0)),"OK")))))))
A20: =IF(COUNTA(B20:G20)=0,"",IF((IF(B20="","Vendor Name, ","")&IF(C20="","State, ",""))<>"","Missing: "&LEFT(IF(B20="","Vendor Name, ","")&IF(C20="","State, ",""),LEN(IF(B20="","Vendor Name, ","")&IF(C20="","State, ",""))-2),IF(COUNTIF($B$3:$B$202,B20)>1,"Vendor "&B20&" is listed twice",IF(ISNA(MATCH(C20,Codes!$E$2:$E$37,0)),"Pick the State from the list",IF(E20="","OK",IF(LEN(TRIM(E20))<>15,"GSTIN must be 15 characters - or leave it blank",IF(LEFT(TRIM(E20),2)<>INDEX(Codes!$F$2:$F$37,MATCH(C20,Codes!$E$2:$E$37,0)),"GSTIN starts with "&LEFT(TRIM(E20),2)&" but "&C20&" is "&INDEX(Codes!$F$2:$F$37,MATCH(C20,Codes!$E$2:$E$37,0)),"OK")))))))
A21: =IF(COUNTA(B21:G21)=0,"",IF((IF(B21="","Vendor Name, ","")&IF(C21="","State, ",""))<>"","Missing: "&LEFT(IF(B21="","Vendor Name, ","")&IF(C21="","State, ",""),LEN(IF(B21="","Vendor Name, ","")&IF(C21="","State, ",""))-2),IF(COUNTIF($B$3:$B$202,B21)>1,"Vendor "&B21&" is listed twice",IF(ISNA(MATCH(C21,Codes!$E$2:$E$37,0)),"Pick the State from the list",IF(E21="","OK",IF(LEN(TRIM(E21))<>15,"GSTIN must be 15 characters - or leave it blank",IF(LEFT(TRIM(E21),2)<>INDEX(Codes!$F$2:$F$37,MATCH(C21,Codes!$E$2:$E$37,0)),"GSTIN starts with "&LEFT(TRIM(E21),2)&" but "&C21&" is "&INDEX(Codes!$F$2:$F$37,MATCH(C21,Codes!$E$2:$E$37,0)),"OK")))))))
... A202: =IF(COUNTA(B202:G202)=0,"",IF((IF(B202="","Vendor Name, ","")&IF(C202="","State, ",""))<>"","Missing: "&LEFT(IF(B202="","Vendor Name, ","")&IF(C202="","State, ",""),LEN(IF(B202="","Vendor Name, ","")&IF(C202="","State, ",""))-2),IF(COUNTIF($B$3:$B$202,B202)>1,"Vendor "&B202&" is listed twice",IF(ISNA(MATCH(C202,Codes!$E$2:$E$37,0)),"Pick the State from the list",IF(E202="","OK",IF(LEN(TRIM(E202))<>15,"GSTIN must be 15 characters - or leave it blank",IF(LEFT(TRIM(E202),2)<>INDEX(Codes!$F$2:$F$37,MATCH(C202,Codes!$E$2:$E$37,0)),"GSTIN starts with "&LEFT(TRIM(E202),2)&" but "&C202&" is "&INDEX(Codes!$F$2:$F$37,MATCH(C202,Codes!$E$2:$E$37,0)),"OK")))))))

Sheet Purchase
A1: Check | B1: PO Ref * | C1: Vendor * | D1: Store * | E1: Design No | F1: Product Type * | G1: Category * | H1: HSN Code * | I1: GST % | J1: Style | K1: Colour | L1: Polish | M1: Size | N1: Stone Type | O1: Stone Colour | P1: Photo | Q1: Qty * | R1: Purchase Rate (₹) * | S1: MRP (₹) * | T1: Amount (₹) | U1: Vendor Invoice No | V1: Received Qty | W1: Received Amount (₹)
A2: # Automatic: says OK, or what to fix | B2: Required. Your name for this PO, e.g. SIY-OCT-01. Same PO Ref = one PO | C2: Required. Pick from the list (Vendors sheet) | D2: Required. Where the goods arrive | E2: Optional. Your label: same label = one design (1, 1, 1). Blank = own design | F2: Required. What it is: Earring, Necklace... | G2: Required. Collection: Antique, Kundan... | H2: Required. Pick from the list (see the Codes sheet) | I2: Auto, from the HSN | J2: Optional. Ball Drop, Cuff... | K2: Optional. Blank if it does not apply | L2: Optional | M2: Optional | N2: Optional | O2: Optional | P2: Optional. Photo file name(s), e.g. EI001-red.jpg, or a.jpg, b.jpg | Q2: Required. Pieces (a pair = 1) | R2: Required. Per piece, including GST, as on the bill | S2: Required. The price printed on the sticker | T2: Automatic: Qty × Rate | U2: When goods arrive: the bill no. Blank = PO only | V2: Only if it differs from Qty (short or extra) | W2: Automatic: received qty × rate
A3: =IF(COUNTA(B3:H3,J3:S3,U3:V3)=0,"",IF((IF(B3="","PO Ref, ","")&IF(C3="","Vendor, ","")&IF(D3="","Store, ","")&IF(F3="","Product Type, ","")&IF(G3="","Category, ","")&IF(H3="","HSN Code, ","")&IF(Q3="","Qty, ","")&IF(R3="","Purchase Rate, ","")&IF(S3="","MRP, ",""))<>"","Missing: "&LEFT(IF(B3="","PO Ref, ","")&IF(C3="","Vendor, ","")&IF(D3="","Store, ","")&IF(F3="","Product Type, ","")&IF(G3="","Category, ","")&IF(H3="","HSN Code, ","")&IF(Q3="","Qty, ","")&IF(R3="","Purchase Rate, ","")&IF(S3="","MRP, ",""),LEN(IF(B3="","PO Ref, ","")&IF(C3="","Vendor, ","")&IF(D3="","Store, ","")&IF(F3="","Product Type, ","")&IF(G3="","Category, ","")&IF(H3="","HSN Code, ","")&IF(Q3="","Qty, ","")&IF(R3="","Purchase Rate, ","")&IF(S3="","MRP, ",""))-2),IF(COUNTIF(Vendors!$B$3:$B$202,C3)=0,"Add vendor "&C3&" on the Vendors sheet",IF(ISNA(MATCH(H3,Codes!$A$2:$A$13,0)),"Pick the HSN Code from the list",IF(AND(E3<>"",COUNTIFS($C$3:$C$1002,C3,$E$3:$E$1002,E3,$F$3:$F$1002,"<>"&F3)+COUNTIFS($C$3:$C$1002,C3,$E$3:$E$1002,E3,$G$3:$G$1002,"<>"&G3)>0),"Design "&E3&" has another Product Type or Category on another row",IF(COUNTIFS($F$3:$F$1002,F3,$G$3:$G$1002,G3,$H$3:$H$1002,"<>"&H3)>0,F3&" + "&G3&" has another HSN Code on another row",IF(AND(V3<>"",U3=""),"Received Qty needs the Vendor Invoice No",IF(AND(U3<>"",COUNTIFS(Bills!$B$3:$B$302,U3,Bills!$C$3:$C$302,C3)=0),"Add bill "&U3&" of "&C3&" on the Bills sheet",IF(S3<R3,"MRP is below the Purchase Rate","OK"))))))))) | I3: =IF(H3="","",IFERROR(INDEX(Codes!$B$2:$B$13,MATCH(H3,Codes!$A$2:$A$13,0)),"")) | T3: =IF(OR(Q3="",R3=""),"",Q3*R3) | W3: =IF(OR(U3="",R3=""),"",IF(V3="",Q3,V3)*R3)
A4: =IF(COUNTA(B4:H4,J4:S4,U4:V4)=0,"",IF((IF(B4="","PO Ref, ","")&IF(C4="","Vendor, ","")&IF(D4="","Store, ","")&IF(F4="","Product Type, ","")&IF(G4="","Category, ","")&IF(H4="","HSN Code, ","")&IF(Q4="","Qty, ","")&IF(R4="","Purchase Rate, ","")&IF(S4="","MRP, ",""))<>"","Missing: "&LEFT(IF(B4="","PO Ref, ","")&IF(C4="","Vendor, ","")&IF(D4="","Store, ","")&IF(F4="","Product Type, ","")&IF(G4="","Category, ","")&IF(H4="","HSN Code, ","")&IF(Q4="","Qty, ","")&IF(R4="","Purchase Rate, ","")&IF(S4="","MRP, ",""),LEN(IF(B4="","PO Ref, ","")&IF(C4="","Vendor, ","")&IF(D4="","Store, ","")&IF(F4="","Product Type, ","")&IF(G4="","Category, ","")&IF(H4="","HSN Code, ","")&IF(Q4="","Qty, ","")&IF(R4="","Purchase Rate, ","")&IF(S4="","MRP, ",""))-2),IF(COUNTIF(Vendors!$B$3:$B$202,C4)=0,"Add vendor "&C4&" on the Vendors sheet",IF(ISNA(MATCH(H4,Codes!$A$2:$A$13,0)),"Pick the HSN Code from the list",IF(AND(E4<>"",COUNTIFS($C$3:$C$1002,C4,$E$3:$E$1002,E4,$F$3:$F$1002,"<>"&F4)+COUNTIFS($C$3:$C$1002,C4,$E$3:$E$1002,E4,$G$3:$G$1002,"<>"&G4)>0),"Design "&E4&" has another Product Type or Category on another row",IF(COUNTIFS($F$3:$F$1002,F4,$G$3:$G$1002,G4,$H$3:$H$1002,"<>"&H4)>0,F4&" + "&G4&" has another HSN Code on another row",IF(AND(V4<>"",U4=""),"Received Qty needs the Vendor Invoice No",IF(AND(U4<>"",COUNTIFS(Bills!$B$3:$B$302,U4,Bills!$C$3:$C$302,C4)=0),"Add bill "&U4&" of "&C4&" on the Bills sheet",IF(S4<R4,"MRP is below the Purchase Rate","OK"))))))))) | I4: =IF(H4="","",IFERROR(INDEX(Codes!$B$2:$B$13,MATCH(H4,Codes!$A$2:$A$13,0)),"")) | T4: =IF(OR(Q4="",R4=""),"",Q4*R4) | W4: =IF(OR(U4="",R4=""),"",IF(V4="",Q4,V4)*R4)
A5: =IF(COUNTA(B5:H5,J5:S5,U5:V5)=0,"",IF((IF(B5="","PO Ref, ","")&IF(C5="","Vendor, ","")&IF(D5="","Store, ","")&IF(F5="","Product Type, ","")&IF(G5="","Category, ","")&IF(H5="","HSN Code, ","")&IF(Q5="","Qty, ","")&IF(R5="","Purchase Rate, ","")&IF(S5="","MRP, ",""))<>"","Missing: "&LEFT(IF(B5="","PO Ref, ","")&IF(C5="","Vendor, ","")&IF(D5="","Store, ","")&IF(F5="","Product Type, ","")&IF(G5="","Category, ","")&IF(H5="","HSN Code, ","")&IF(Q5="","Qty, ","")&IF(R5="","Purchase Rate, ","")&IF(S5="","MRP, ",""),LEN(IF(B5="","PO Ref, ","")&IF(C5="","Vendor, ","")&IF(D5="","Store, ","")&IF(F5="","Product Type, ","")&IF(G5="","Category, ","")&IF(H5="","HSN Code, ","")&IF(Q5="","Qty, ","")&IF(R5="","Purchase Rate, ","")&IF(S5="","MRP, ",""))-2),IF(COUNTIF(Vendors!$B$3:$B$202,C5)=0,"Add vendor "&C5&" on the Vendors sheet",IF(ISNA(MATCH(H5,Codes!$A$2:$A$13,0)),"Pick the HSN Code from the list",IF(AND(E5<>"",COUNTIFS($C$3:$C$1002,C5,$E$3:$E$1002,E5,$F$3:$F$1002,"<>"&F5)+COUNTIFS($C$3:$C$1002,C5,$E$3:$E$1002,E5,$G$3:$G$1002,"<>"&G5)>0),"Design "&E5&" has another Product Type or Category on another row",IF(COUNTIFS($F$3:$F$1002,F5,$G$3:$G$1002,G5,$H$3:$H$1002,"<>"&H5)>0,F5&" + "&G5&" has another HSN Code on another row",IF(AND(V5<>"",U5=""),"Received Qty needs the Vendor Invoice No",IF(AND(U5<>"",COUNTIFS(Bills!$B$3:$B$302,U5,Bills!$C$3:$C$302,C5)=0),"Add bill "&U5&" of "&C5&" on the Bills sheet",IF(S5<R5,"MRP is below the Purchase Rate","OK"))))))))) | I5: =IF(H5="","",IFERROR(INDEX(Codes!$B$2:$B$13,MATCH(H5,Codes!$A$2:$A$13,0)),"")) | T5: =IF(OR(Q5="",R5=""),"",Q5*R5) | W5: =IF(OR(U5="",R5=""),"",IF(V5="",Q5,V5)*R5)
A6: =IF(COUNTA(B6:H6,J6:S6,U6:V6)=0,"",IF((IF(B6="","PO Ref, ","")&IF(C6="","Vendor, ","")&IF(D6="","Store, ","")&IF(F6="","Product Type, ","")&IF(G6="","Category, ","")&IF(H6="","HSN Code, ","")&IF(Q6="","Qty, ","")&IF(R6="","Purchase Rate, ","")&IF(S6="","MRP, ",""))<>"","Missing: "&LEFT(IF(B6="","PO Ref, ","")&IF(C6="","Vendor, ","")&IF(D6="","Store, ","")&IF(F6="","Product Type, ","")&IF(G6="","Category, ","")&IF(H6="","HSN Code, ","")&IF(Q6="","Qty, ","")&IF(R6="","Purchase Rate, ","")&IF(S6="","MRP, ",""),LEN(IF(B6="","PO Ref, ","")&IF(C6="","Vendor, ","")&IF(D6="","Store, ","")&IF(F6="","Product Type, ","")&IF(G6="","Category, ","")&IF(H6="","HSN Code, ","")&IF(Q6="","Qty, ","")&IF(R6="","Purchase Rate, ","")&IF(S6="","MRP, ",""))-2),IF(COUNTIF(Vendors!$B$3:$B$202,C6)=0,"Add vendor "&C6&" on the Vendors sheet",IF(ISNA(MATCH(H6,Codes!$A$2:$A$13,0)),"Pick the HSN Code from the list",IF(AND(E6<>"",COUNTIFS($C$3:$C$1002,C6,$E$3:$E$1002,E6,$F$3:$F$1002,"<>"&F6)+COUNTIFS($C$3:$C$1002,C6,$E$3:$E$1002,E6,$G$3:$G$1002,"<>"&G6)>0),"Design "&E6&" has another Product Type or Category on another row",IF(COUNTIFS($F$3:$F$1002,F6,$G$3:$G$1002,G6,$H$3:$H$1002,"<>"&H6)>0,F6&" + "&G6&" has another HSN Code on another row",IF(AND(V6<>"",U6=""),"Received Qty needs the Vendor Invoice No",IF(AND(U6<>"",COUNTIFS(Bills!$B$3:$B$302,U6,Bills!$C$3:$C$302,C6)=0),"Add bill "&U6&" of "&C6&" on the Bills sheet",IF(S6<R6,"MRP is below the Purchase Rate","OK"))))))))) | I6: =IF(H6="","",IFERROR(INDEX(Codes!$B$2:$B$13,MATCH(H6,Codes!$A$2:$A$13,0)),"")) | T6: =IF(OR(Q6="",R6=""),"",Q6*R6) | W6: =IF(OR(U6="",R6=""),"",IF(V6="",Q6,V6)*R6)
A7: =IF(COUNTA(B7:H7,J7:S7,U7:V7)=0,"",IF((IF(B7="","PO Ref, ","")&IF(C7="","Vendor, ","")&IF(D7="","Store, ","")&IF(F7="","Product Type, ","")&IF(G7="","Category, ","")&IF(H7="","HSN Code, ","")&IF(Q7="","Qty, ","")&IF(R7="","Purchase Rate, ","")&IF(S7="","MRP, ",""))<>"","Missing: "&LEFT(IF(B7="","PO Ref, ","")&IF(C7="","Vendor, ","")&IF(D7="","Store, ","")&IF(F7="","Product Type, ","")&IF(G7="","Category, ","")&IF(H7="","HSN Code, ","")&IF(Q7="","Qty, ","")&IF(R7="","Purchase Rate, ","")&IF(S7="","MRP, ",""),LEN(IF(B7="","PO Ref, ","")&IF(C7="","Vendor, ","")&IF(D7="","Store, ","")&IF(F7="","Product Type, ","")&IF(G7="","Category, ","")&IF(H7="","HSN Code, ","")&IF(Q7="","Qty, ","")&IF(R7="","Purchase Rate, ","")&IF(S7="","MRP, ",""))-2),IF(COUNTIF(Vendors!$B$3:$B$202,C7)=0,"Add vendor "&C7&" on the Vendors sheet",IF(ISNA(MATCH(H7,Codes!$A$2:$A$13,0)),"Pick the HSN Code from the list",IF(AND(E7<>"",COUNTIFS($C$3:$C$1002,C7,$E$3:$E$1002,E7,$F$3:$F$1002,"<>"&F7)+COUNTIFS($C$3:$C$1002,C7,$E$3:$E$1002,E7,$G$3:$G$1002,"<>"&G7)>0),"Design "&E7&" has another Product Type or Category on another row",IF(COUNTIFS($F$3:$F$1002,F7,$G$3:$G$1002,G7,$H$3:$H$1002,"<>"&H7)>0,F7&" + "&G7&" has another HSN Code on another row",IF(AND(V7<>"",U7=""),"Received Qty needs the Vendor Invoice No",IF(AND(U7<>"",COUNTIFS(Bills!$B$3:$B$302,U7,Bills!$C$3:$C$302,C7)=0),"Add bill "&U7&" of "&C7&" on the Bills sheet",IF(S7<R7,"MRP is below the Purchase Rate","OK"))))))))) | I7: =IF(H7="","",IFERROR(INDEX(Codes!$B$2:$B$13,MATCH(H7,Codes!$A$2:$A$13,0)),"")) | T7: =IF(OR(Q7="",R7=""),"",Q7*R7) | W7: =IF(OR(U7="",R7=""),"",IF(V7="",Q7,V7)*R7)
A8: =IF(COUNTA(B8:H8,J8:S8,U8:V8)=0,"",IF((IF(B8="","PO Ref, ","")&IF(C8="","Vendor, ","")&IF(D8="","Store, ","")&IF(F8="","Product Type, ","")&IF(G8="","Category, ","")&IF(H8="","HSN Code, ","")&IF(Q8="","Qty, ","")&IF(R8="","Purchase Rate, ","")&IF(S8="","MRP, ",""))<>"","Missing: "&LEFT(IF(B8="","PO Ref, ","")&IF(C8="","Vendor, ","")&IF(D8="","Store, ","")&IF(F8="","Product Type, ","")&IF(G8="","Category, ","")&IF(H8="","HSN Code, ","")&IF(Q8="","Qty, ","")&IF(R8="","Purchase Rate, ","")&IF(S8="","MRP, ",""),LEN(IF(B8="","PO Ref, ","")&IF(C8="","Vendor, ","")&IF(D8="","Store, ","")&IF(F8="","Product Type, ","")&IF(G8="","Category, ","")&IF(H8="","HSN Code, ","")&IF(Q8="","Qty, ","")&IF(R8="","Purchase Rate, ","")&IF(S8="","MRP, ",""))-2),IF(COUNTIF(Vendors!$B$3:$B$202,C8)=0,"Add vendor "&C8&" on the Vendors sheet",IF(ISNA(MATCH(H8,Codes!$A$2:$A$13,0)),"Pick the HSN Code from the list",IF(AND(E8<>"",COUNTIFS($C$3:$C$1002,C8,$E$3:$E$1002,E8,$F$3:$F$1002,"<>"&F8)+COUNTIFS($C$3:$C$1002,C8,$E$3:$E$1002,E8,$G$3:$G$1002,"<>"&G8)>0),"Design "&E8&" has another Product Type or Category on another row",IF(COUNTIFS($F$3:$F$1002,F8,$G$3:$G$1002,G8,$H$3:$H$1002,"<>"&H8)>0,F8&" + "&G8&" has another HSN Code on another row",IF(AND(V8<>"",U8=""),"Received Qty needs the Vendor Invoice No",IF(AND(U8<>"",COUNTIFS(Bills!$B$3:$B$302,U8,Bills!$C$3:$C$302,C8)=0),"Add bill "&U8&" of "&C8&" on the Bills sheet",IF(S8<R8,"MRP is below the Purchase Rate","OK"))))))))) | I8: =IF(H8="","",IFERROR(INDEX(Codes!$B$2:$B$13,MATCH(H8,Codes!$A$2:$A$13,0)),"")) | T8: =IF(OR(Q8="",R8=""),"",Q8*R8) | W8: =IF(OR(U8="",R8=""),"",IF(V8="",Q8,V8)*R8)
A9: =IF(COUNTA(B9:H9,J9:S9,U9:V9)=0,"",IF((IF(B9="","PO Ref, ","")&IF(C9="","Vendor, ","")&IF(D9="","Store, ","")&IF(F9="","Product Type, ","")&IF(G9="","Category, ","")&IF(H9="","HSN Code, ","")&IF(Q9="","Qty, ","")&IF(R9="","Purchase Rate, ","")&IF(S9="","MRP, ",""))<>"","Missing: "&LEFT(IF(B9="","PO Ref, ","")&IF(C9="","Vendor, ","")&IF(D9="","Store, ","")&IF(F9="","Product Type, ","")&IF(G9="","Category, ","")&IF(H9="","HSN Code, ","")&IF(Q9="","Qty, ","")&IF(R9="","Purchase Rate, ","")&IF(S9="","MRP, ",""),LEN(IF(B9="","PO Ref, ","")&IF(C9="","Vendor, ","")&IF(D9="","Store, ","")&IF(F9="","Product Type, ","")&IF(G9="","Category, ","")&IF(H9="","HSN Code, ","")&IF(Q9="","Qty, ","")&IF(R9="","Purchase Rate, ","")&IF(S9="","MRP, ",""))-2),IF(COUNTIF(Vendors!$B$3:$B$202,C9)=0,"Add vendor "&C9&" on the Vendors sheet",IF(ISNA(MATCH(H9,Codes!$A$2:$A$13,0)),"Pick the HSN Code from the list",IF(AND(E9<>"",COUNTIFS($C$3:$C$1002,C9,$E$3:$E$1002,E9,$F$3:$F$1002,"<>"&F9)+COUNTIFS($C$3:$C$1002,C9,$E$3:$E$1002,E9,$G$3:$G$1002,"<>"&G9)>0),"Design "&E9&" has another Product Type or Category on another row",IF(COUNTIFS($F$3:$F$1002,F9,$G$3:$G$1002,G9,$H$3:$H$1002,"<>"&H9)>0,F9&" + "&G9&" has another HSN Code on another row",IF(AND(V9<>"",U9=""),"Received Qty needs the Vendor Invoice No",IF(AND(U9<>"",COUNTIFS(Bills!$B$3:$B$302,U9,Bills!$C$3:$C$302,C9)=0),"Add bill "&U9&" of "&C9&" on the Bills sheet",IF(S9<R9,"MRP is below the Purchase Rate","OK"))))))))) | I9: =IF(H9="","",IFERROR(INDEX(Codes!$B$2:$B$13,MATCH(H9,Codes!$A$2:$A$13,0)),"")) | T9: =IF(OR(Q9="",R9=""),"",Q9*R9) | W9: =IF(OR(U9="",R9=""),"",IF(V9="",Q9,V9)*R9)
A10: =IF(COUNTA(B10:H10,J10:S10,U10:V10)=0,"",IF((IF(B10="","PO Ref, ","")&IF(C10="","Vendor, ","")&IF(D10="","Store, ","")&IF(F10="","Product Type, ","")&IF(G10="","Category, ","")&IF(H10="","HSN Code, ","")&IF(Q10="","Qty, ","")&IF(R10="","Purchase Rate, ","")&IF(S10="","MRP, ",""))<>"","Missing: "&LEFT(IF(B10="","PO Ref, ","")&IF(C10="","Vendor, ","")&IF(D10="","Store, ","")&IF(F10="","Product Type, ","")&IF(G10="","Category, ","")&IF(H10="","HSN Code, ","")&IF(Q10="","Qty, ","")&IF(R10="","Purchase Rate, ","")&IF(S10="","MRP, ",""),LEN(IF(B10="","PO Ref, ","")&IF(C10="","Vendor, ","")&IF(D10="","Store, ","")&IF(F10="","Product Type, ","")&IF(G10="","Category, ","")&IF(H10="","HSN Code, ","")&IF(Q10="","Qty, ","")&IF(R10="","Purchase Rate, ","")&IF(S10="","MRP, ",""))-2),IF(COUNTIF(Vendors!$B$3:$B$202,C10)=0,"Add vendor "&C10&" on the Vendors sheet",IF(ISNA(MATCH(H10,Codes!$A$2:$A$13,0)),"Pick the HSN Code from the list",IF(AND(E10<>"",COUNTIFS($C$3:$C$1002,C10,$E$3:$E$1002,E10,$F$3:$F$1002,"<>"&F10)+COUNTIFS($C$3:$C$1002,C10,$E$3:$E$1002,E10,$G$3:$G$1002,"<>"&G10)>0),"Design "&E10&" has another Product Type or Category on another row",IF(COUNTIFS($F$3:$F$1002,F10,$G$3:$G$1002,G10,$H$3:$H$1002,"<>"&H10)>0,F10&" + "&G10&" has another HSN Code on another row",IF(AND(V10<>"",U10=""),"Received Qty needs the Vendor Invoice No",IF(AND(U10<>"",COUNTIFS(Bills!$B$3:$B$302,U10,Bills!$C$3:$C$302,C10)=0),"Add bill "&U10&" of "&C10&" on the Bills sheet",IF(S10<R10,"MRP is below the Purchase Rate","OK"))))))))) | I10: =IF(H10="","",IFERROR(INDEX(Codes!$B$2:$B$13,MATCH(H10,Codes!$A$2:$A$13,0)),"")) | T10: =IF(OR(Q10="",R10=""),"",Q10*R10) | W10: =IF(OR(U10="",R10=""),"",IF(V10="",Q10,V10)*R10)
A11: =IF(COUNTA(B11:H11,J11:S11,U11:V11)=0,"",IF((IF(B11="","PO Ref, ","")&IF(C11="","Vendor, ","")&IF(D11="","Store, ","")&IF(F11="","Product Type, ","")&IF(G11="","Category, ","")&IF(H11="","HSN Code, ","")&IF(Q11="","Qty, ","")&IF(R11="","Purchase Rate, ","")&IF(S11="","MRP, ",""))<>"","Missing: "&LEFT(IF(B11="","PO Ref, ","")&IF(C11="","Vendor, ","")&IF(D11="","Store, ","")&IF(F11="","Product Type, ","")&IF(G11="","Category, ","")&IF(H11="","HSN Code, ","")&IF(Q11="","Qty, ","")&IF(R11="","Purchase Rate, ","")&IF(S11="","MRP, ",""),LEN(IF(B11="","PO Ref, ","")&IF(C11="","Vendor, ","")&IF(D11="","Store, ","")&IF(F11="","Product Type, ","")&IF(G11="","Category, ","")&IF(H11="","HSN Code, ","")&IF(Q11="","Qty, ","")&IF(R11="","Purchase Rate, ","")&IF(S11="","MRP, ",""))-2),IF(COUNTIF(Vendors!$B$3:$B$202,C11)=0,"Add vendor "&C11&" on the Vendors sheet",IF(ISNA(MATCH(H11,Codes!$A$2:$A$13,0)),"Pick the HSN Code from the list",IF(AND(E11<>"",COUNTIFS($C$3:$C$1002,C11,$E$3:$E$1002,E11,$F$3:$F$1002,"<>"&F11)+COUNTIFS($C$3:$C$1002,C11,$E$3:$E$1002,E11,$G$3:$G$1002,"<>"&G11)>0),"Design "&E11&" has another Product Type or Category on another row",IF(COUNTIFS($F$3:$F$1002,F11,$G$3:$G$1002,G11,$H$3:$H$1002,"<>"&H11)>0,F11&" + "&G11&" has another HSN Code on another row",IF(AND(V11<>"",U11=""),"Received Qty needs the Vendor Invoice No",IF(AND(U11<>"",COUNTIFS(Bills!$B$3:$B$302,U11,Bills!$C$3:$C$302,C11)=0),"Add bill "&U11&" of "&C11&" on the Bills sheet",IF(S11<R11,"MRP is below the Purchase Rate","OK"))))))))) | I11: =IF(H11="","",IFERROR(INDEX(Codes!$B$2:$B$13,MATCH(H11,Codes!$A$2:$A$13,0)),"")) | T11: =IF(OR(Q11="",R11=""),"",Q11*R11) | W11: =IF(OR(U11="",R11=""),"",IF(V11="",Q11,V11)*R11)
A12: =IF(COUNTA(B12:H12,J12:S12,U12:V12)=0,"",IF((IF(B12="","PO Ref, ","")&IF(C12="","Vendor, ","")&IF(D12="","Store, ","")&IF(F12="","Product Type, ","")&IF(G12="","Category, ","")&IF(H12="","HSN Code, ","")&IF(Q12="","Qty, ","")&IF(R12="","Purchase Rate, ","")&IF(S12="","MRP, ",""))<>"","Missing: "&LEFT(IF(B12="","PO Ref, ","")&IF(C12="","Vendor, ","")&IF(D12="","Store, ","")&IF(F12="","Product Type, ","")&IF(G12="","Category, ","")&IF(H12="","HSN Code, ","")&IF(Q12="","Qty, ","")&IF(R12="","Purchase Rate, ","")&IF(S12="","MRP, ",""),LEN(IF(B12="","PO Ref, ","")&IF(C12="","Vendor, ","")&IF(D12="","Store, ","")&IF(F12="","Product Type, ","")&IF(G12="","Category, ","")&IF(H12="","HSN Code, ","")&IF(Q12="","Qty, ","")&IF(R12="","Purchase Rate, ","")&IF(S12="","MRP, ",""))-2),IF(COUNTIF(Vendors!$B$3:$B$202,C12)=0,"Add vendor "&C12&" on the Vendors sheet",IF(ISNA(MATCH(H12,Codes!$A$2:$A$13,0)),"Pick the HSN Code from the list",IF(AND(E12<>"",COUNTIFS($C$3:$C$1002,C12,$E$3:$E$1002,E12,$F$3:$F$1002,"<>"&F12)+COUNTIFS($C$3:$C$1002,C12,$E$3:$E$1002,E12,$G$3:$G$1002,"<>"&G12)>0),"Design "&E12&" has another Product Type or Category on another row",IF(COUNTIFS($F$3:$F$1002,F12,$G$3:$G$1002,G12,$H$3:$H$1002,"<>"&H12)>0,F12&" + "&G12&" has another HSN Code on another row",IF(AND(V12<>"",U12=""),"Received Qty needs the Vendor Invoice No",IF(AND(U12<>"",COUNTIFS(Bills!$B$3:$B$302,U12,Bills!$C$3:$C$302,C12)=0),"Add bill "&U12&" of "&C12&" on the Bills sheet",IF(S12<R12,"MRP is below the Purchase Rate","OK"))))))))) | I12: =IF(H12="","",IFERROR(INDEX(Codes!$B$2:$B$13,MATCH(H12,Codes!$A$2:$A$13,0)),"")) | T12: =IF(OR(Q12="",R12=""),"",Q12*R12) | W12: =IF(OR(U12="",R12=""),"",IF(V12="",Q12,V12)*R12)
A13: =IF(COUNTA(B13:H13,J13:S13,U13:V13)=0,"",IF((IF(B13="","PO Ref, ","")&IF(C13="","Vendor, ","")&IF(D13="","Store, ","")&IF(F13="","Product Type, ","")&IF(G13="","Category, ","")&IF(H13="","HSN Code, ","")&IF(Q13="","Qty, ","")&IF(R13="","Purchase Rate, ","")&IF(S13="","MRP, ",""))<>"","Missing: "&LEFT(IF(B13="","PO Ref, ","")&IF(C13="","Vendor, ","")&IF(D13="","Store, ","")&IF(F13="","Product Type, ","")&IF(G13="","Category, ","")&IF(H13="","HSN Code, ","")&IF(Q13="","Qty, ","")&IF(R13="","Purchase Rate, ","")&IF(S13="","MRP, ",""),LEN(IF(B13="","PO Ref, ","")&IF(C13="","Vendor, ","")&IF(D13="","Store, ","")&IF(F13="","Product Type, ","")&IF(G13="","Category, ","")&IF(H13="","HSN Code, ","")&IF(Q13="","Qty, ","")&IF(R13="","Purchase Rate, ","")&IF(S13="","MRP, ",""))-2),IF(COUNTIF(Vendors!$B$3:$B$202,C13)=0,"Add vendor "&C13&" on the Vendors sheet",IF(ISNA(MATCH(H13,Codes!$A$2:$A$13,0)),"Pick the HSN Code from the list",IF(AND(E13<>"",COUNTIFS($C$3:$C$1002,C13,$E$3:$E$1002,E13,$F$3:$F$1002,"<>"&F13)+COUNTIFS($C$3:$C$1002,C13,$E$3:$E$1002,E13,$G$3:$G$1002,"<>"&G13)>0),"Design "&E13&" has another Product Type or Category on another row",IF(COUNTIFS($F$3:$F$1002,F13,$G$3:$G$1002,G13,$H$3:$H$1002,"<>"&H13)>0,F13&" + "&G13&" has another HSN Code on another row",IF(AND(V13<>"",U13=""),"Received Qty needs the Vendor Invoice No",IF(AND(U13<>"",COUNTIFS(Bills!$B$3:$B$302,U13,Bills!$C$3:$C$302,C13)=0),"Add bill "&U13&" of "&C13&" on the Bills sheet",IF(S13<R13,"MRP is below the Purchase Rate","OK"))))))))) | I13: =IF(H13="","",IFERROR(INDEX(Codes!$B$2:$B$13,MATCH(H13,Codes!$A$2:$A$13,0)),"")) | T13: =IF(OR(Q13="",R13=""),"",Q13*R13) | W13: =IF(OR(U13="",R13=""),"",IF(V13="",Q13,V13)*R13)
A14: =IF(COUNTA(B14:H14,J14:S14,U14:V14)=0,"",IF((IF(B14="","PO Ref, ","")&IF(C14="","Vendor, ","")&IF(D14="","Store, ","")&IF(F14="","Product Type, ","")&IF(G14="","Category, ","")&IF(H14="","HSN Code, ","")&IF(Q14="","Qty, ","")&IF(R14="","Purchase Rate, ","")&IF(S14="","MRP, ",""))<>"","Missing: "&LEFT(IF(B14="","PO Ref, ","")&IF(C14="","Vendor, ","")&IF(D14="","Store, ","")&IF(F14="","Product Type, ","")&IF(G14="","Category, ","")&IF(H14="","HSN Code, ","")&IF(Q14="","Qty, ","")&IF(R14="","Purchase Rate, ","")&IF(S14="","MRP, ",""),LEN(IF(B14="","PO Ref, ","")&IF(C14="","Vendor, ","")&IF(D14="","Store, ","")&IF(F14="","Product Type, ","")&IF(G14="","Category, ","")&IF(H14="","HSN Code, ","")&IF(Q14="","Qty, ","")&IF(R14="","Purchase Rate, ","")&IF(S14="","MRP, ",""))-2),IF(COUNTIF(Vendors!$B$3:$B$202,C14)=0,"Add vendor "&C14&" on the Vendors sheet",IF(ISNA(MATCH(H14,Codes!$A$2:$A$13,0)),"Pick the HSN Code from the list",IF(AND(E14<>"",COUNTIFS($C$3:$C$1002,C14,$E$3:$E$1002,E14,$F$3:$F$1002,"<>"&F14)+COUNTIFS($C$3:$C$1002,C14,$E$3:$E$1002,E14,$G$3:$G$1002,"<>"&G14)>0),"Design "&E14&" has another Product Type or Category on another row",IF(COUNTIFS($F$3:$F$1002,F14,$G$3:$G$1002,G14,$H$3:$H$1002,"<>"&H14)>0,F14&" + "&G14&" has another HSN Code on another row",IF(AND(V14<>"",U14=""),"Received Qty needs the Vendor Invoice No",IF(AND(U14<>"",COUNTIFS(Bills!$B$3:$B$302,U14,Bills!$C$3:$C$302,C14)=0),"Add bill "&U14&" of "&C14&" on the Bills sheet",IF(S14<R14,"MRP is below the Purchase Rate","OK"))))))))) | I14: =IF(H14="","",IFERROR(INDEX(Codes!$B$2:$B$13,MATCH(H14,Codes!$A$2:$A$13,0)),"")) | T14: =IF(OR(Q14="",R14=""),"",Q14*R14) | W14: =IF(OR(U14="",R14=""),"",IF(V14="",Q14,V14)*R14)
... A1002: =IF(COUNTA(B1002:H1002,J1002:S1002,U1002:V1002)=0,"",IF((IF(B1002="","PO Ref, ","")&IF(C1002="","Vendor, ","")&IF(D1002="","Store, ","")&IF(F1002="","Product Type, ","")&IF(G1002="","Category, ","")&IF(H1002="","HSN Code, ","")&IF(Q1002="","Qty, ","")&IF(R1002="","Purchase Rate, ","")&IF(S1002="","MRP, ",""))<>"","Missing: "&LEFT(IF(B1002="","PO Ref, ","")&IF(C1002="","Vendor, ","")&IF(D1002="","Store, ","")&IF(F1002="","Product Type, ","")&IF(G1002="","Category, ","")&IF(H1002="","HSN Code, ","")&IF(Q1002="","Qty, ","")&IF(R1002="","Purchase Rate, ","")&IF(S1002="","MRP, ",""),LEN(IF(B1002="","PO Ref, ","")&IF(C1002="","Vendor, ","")&IF(D1002="","Store, ","")&IF(F1002="","Product Type, ","")&IF(G1002="","Category, ","")&IF(H1002="","HSN Code, ","")&IF(Q1002="","Qty, ","")&IF(R1002="","Purchase Rate, ","")&IF(S1002="","MRP, ",""))-2),IF(COUNTIF(Vendors!$B$3:$B$202,C1002)=0,"Add vendor "&C1002&" on the Vendors sheet",IF(ISNA(MATCH(H1002,Codes!$A$2:$A$13,0)),"Pick the HSN Code from the list",IF(AND(E1002<>"",COUNTIFS($C$3:$C$1002,C1002,$E$3:$E$1002,E1002,$F$3:$F$1002,"<>"&F1002)+COUNTIFS($C$3:$C$1002,C1002,$E$3:$E$1002,E1002,$G$3:$G$1002,"<>"&G1002)>0),"Design "&E1002&" has another Product Type or Category on another row",IF(COUNTIFS($F$3:$F$1002,F1002,$G$3:$G$1002,G1002,$H$3:$H$1002,"<>"&H1002)>0,F1002&" + "&G1002&" has another HSN Code on another row",IF(AND(V1002<>"",U1002=""),"Received Qty needs the Vendor Invoice No",IF(AND(U1002<>"",COUNTIFS(Bills!$B$3:$B$302,U1002,Bills!$C$3:$C$302,C1002)=0),"Add bill "&U1002&" of "&C1002&" on the Bills sheet",IF(S1002<R1002,"MRP is below the Purchase Rate","OK"))))))))) | I1002: =IF(H1002="","",IFERROR(INDEX(Codes!$B$2:$B$13,MATCH(H1002,Codes!$A$2:$A$13,0)),"")) | T1002: =IF(OR(Q1002="",R1002=""),"",Q1002*R1002) | W1002: =IF(OR(U1002="",R1002=""),"",IF(V1002="",Q1002,V1002)*R1002)

Sheet Bills
A1: Check | B1: Vendor Invoice No * | C1: Vendor * | D1: Invoice Date * | E1: Invoice Total (₹) * | F1: Rows Total (₹) | G1: Difference (₹)
A2: # Automatic: says OK, or what to fix | B2: Required. Exactly as typed on the Purchase sheet | C2: Required. Pick from the list | D2: Required. Date on the bill | E2: Required. Grand total on the bill, including GST | F2: Automatic: sum of Received Amount for this bill | G2: Automatic: bill minus rows. Must be within ₹1
A3: =IF(COUNTA(B3:E3)=0,"",IF((IF(B3="","Vendor Invoice No, ","")&IF(C3="","Vendor, ","")&IF(D3="","Invoice Date, ","")&IF(E3="","Invoice Total, ",""))<>"","Missing: "&LEFT(IF(B3="","Vendor Invoice No, ","")&IF(C3="","Vendor, ","")&IF(D3="","Invoice Date, ","")&IF(E3="","Invoice Total, ",""),LEN(IF(B3="","Vendor Invoice No, ","")&IF(C3="","Vendor, ","")&IF(D3="","Invoice Date, ","")&IF(E3="","Invoice Total, ",""))-2),IF(COUNTIFS($B$3:$B$302,B3,$C$3:$C$302,C3)>1,"Bill "&B3&" is listed twice",IF(F3=0,"No Purchase row has this bill no for this vendor",IF(ABS(G3)>1,"Bill and rows differ by ₹"&TEXT(G3,"#,##0.00"),"OK"))))) | F3: =IF(B3="","",SUMIFS(Purchase!$W$3:$W$1002,Purchase!$U$3:$U$1002,B3,Purchase!$C$3:$C$1002,C3)) | G3: =IF(OR(B3="",E3=""),"",E3-F3)
A4: =IF(COUNTA(B4:E4)=0,"",IF((IF(B4="","Vendor Invoice No, ","")&IF(C4="","Vendor, ","")&IF(D4="","Invoice Date, ","")&IF(E4="","Invoice Total, ",""))<>"","Missing: "&LEFT(IF(B4="","Vendor Invoice No, ","")&IF(C4="","Vendor, ","")&IF(D4="","Invoice Date, ","")&IF(E4="","Invoice Total, ",""),LEN(IF(B4="","Vendor Invoice No, ","")&IF(C4="","Vendor, ","")&IF(D4="","Invoice Date, ","")&IF(E4="","Invoice Total, ",""))-2),IF(COUNTIFS($B$3:$B$302,B4,$C$3:$C$302,C4)>1,"Bill "&B4&" is listed twice",IF(F4=0,"No Purchase row has this bill no for this vendor",IF(ABS(G4)>1,"Bill and rows differ by ₹"&TEXT(G4,"#,##0.00"),"OK"))))) | F4: =IF(B4="","",SUMIFS(Purchase!$W$3:$W$1002,Purchase!$U$3:$U$1002,B4,Purchase!$C$3:$C$1002,C4)) | G4: =IF(OR(B4="",E4=""),"",E4-F4)
A5: =IF(COUNTA(B5:E5)=0,"",IF((IF(B5="","Vendor Invoice No, ","")&IF(C5="","Vendor, ","")&IF(D5="","Invoice Date, ","")&IF(E5="","Invoice Total, ",""))<>"","Missing: "&LEFT(IF(B5="","Vendor Invoice No, ","")&IF(C5="","Vendor, ","")&IF(D5="","Invoice Date, ","")&IF(E5="","Invoice Total, ",""),LEN(IF(B5="","Vendor Invoice No, ","")&IF(C5="","Vendor, ","")&IF(D5="","Invoice Date, ","")&IF(E5="","Invoice Total, ",""))-2),IF(COUNTIFS($B$3:$B$302,B5,$C$3:$C$302,C5)>1,"Bill "&B5&" is listed twice",IF(F5=0,"No Purchase row has this bill no for this vendor",IF(ABS(G5)>1,"Bill and rows differ by ₹"&TEXT(G5,"#,##0.00"),"OK"))))) | F5: =IF(B5="","",SUMIFS(Purchase!$W$3:$W$1002,Purchase!$U$3:$U$1002,B5,Purchase!$C$3:$C$1002,C5)) | G5: =IF(OR(B5="",E5=""),"",E5-F5)
A6: =IF(COUNTA(B6:E6)=0,"",IF((IF(B6="","Vendor Invoice No, ","")&IF(C6="","Vendor, ","")&IF(D6="","Invoice Date, ","")&IF(E6="","Invoice Total, ",""))<>"","Missing: "&LEFT(IF(B6="","Vendor Invoice No, ","")&IF(C6="","Vendor, ","")&IF(D6="","Invoice Date, ","")&IF(E6="","Invoice Total, ",""),LEN(IF(B6="","Vendor Invoice No, ","")&IF(C6="","Vendor, ","")&IF(D6="","Invoice Date, ","")&IF(E6="","Invoice Total, ",""))-2),IF(COUNTIFS($B$3:$B$302,B6,$C$3:$C$302,C6)>1,"Bill "&B6&" is listed twice",IF(F6=0,"No Purchase row has this bill no for this vendor",IF(ABS(G6)>1,"Bill and rows differ by ₹"&TEXT(G6,"#,##0.00"),"OK"))))) | F6: =IF(B6="","",SUMIFS(Purchase!$W$3:$W$1002,Purchase!$U$3:$U$1002,B6,Purchase!$C$3:$C$1002,C6)) | G6: =IF(OR(B6="",E6=""),"",E6-F6)
A7: =IF(COUNTA(B7:E7)=0,"",IF((IF(B7="","Vendor Invoice No, ","")&IF(C7="","Vendor, ","")&IF(D7="","Invoice Date, ","")&IF(E7="","Invoice Total, ",""))<>"","Missing: "&LEFT(IF(B7="","Vendor Invoice No, ","")&IF(C7="","Vendor, ","")&IF(D7="","Invoice Date, ","")&IF(E7="","Invoice Total, ",""),LEN(IF(B7="","Vendor Invoice No, ","")&IF(C7="","Vendor, ","")&IF(D7="","Invoice Date, ","")&IF(E7="","Invoice Total, ",""))-2),IF(COUNTIFS($B$3:$B$302,B7,$C$3:$C$302,C7)>1,"Bill "&B7&" is listed twice",IF(F7=0,"No Purchase row has this bill no for this vendor",IF(ABS(G7)>1,"Bill and rows differ by ₹"&TEXT(G7,"#,##0.00"),"OK"))))) | F7: =IF(B7="","",SUMIFS(Purchase!$W$3:$W$1002,Purchase!$U$3:$U$1002,B7,Purchase!$C$3:$C$1002,C7)) | G7: =IF(OR(B7="",E7=""),"",E7-F7)
A8: =IF(COUNTA(B8:E8)=0,"",IF((IF(B8="","Vendor Invoice No, ","")&IF(C8="","Vendor, ","")&IF(D8="","Invoice Date, ","")&IF(E8="","Invoice Total, ",""))<>"","Missing: "&LEFT(IF(B8="","Vendor Invoice No, ","")&IF(C8="","Vendor, ","")&IF(D8="","Invoice Date, ","")&IF(E8="","Invoice Total, ",""),LEN(IF(B8="","Vendor Invoice No, ","")&IF(C8="","Vendor, ","")&IF(D8="","Invoice Date, ","")&IF(E8="","Invoice Total, ",""))-2),IF(COUNTIFS($B$3:$B$302,B8,$C$3:$C$302,C8)>1,"Bill "&B8&" is listed twice",IF(F8=0,"No Purchase row has this bill no for this vendor",IF(ABS(G8)>1,"Bill and rows differ by ₹"&TEXT(G8,"#,##0.00"),"OK"))))) | F8: =IF(B8="","",SUMIFS(Purchase!$W$3:$W$1002,Purchase!$U$3:$U$1002,B8,Purchase!$C$3:$C$1002,C8)) | G8: =IF(OR(B8="",E8=""),"",E8-F8)
A9: =IF(COUNTA(B9:E9)=0,"",IF((IF(B9="","Vendor Invoice No, ","")&IF(C9="","Vendor, ","")&IF(D9="","Invoice Date, ","")&IF(E9="","Invoice Total, ",""))<>"","Missing: "&LEFT(IF(B9="","Vendor Invoice No, ","")&IF(C9="","Vendor, ","")&IF(D9="","Invoice Date, ","")&IF(E9="","Invoice Total, ",""),LEN(IF(B9="","Vendor Invoice No, ","")&IF(C9="","Vendor, ","")&IF(D9="","Invoice Date, ","")&IF(E9="","Invoice Total, ",""))-2),IF(COUNTIFS($B$3:$B$302,B9,$C$3:$C$302,C9)>1,"Bill "&B9&" is listed twice",IF(F9=0,"No Purchase row has this bill no for this vendor",IF(ABS(G9)>1,"Bill and rows differ by ₹"&TEXT(G9,"#,##0.00"),"OK"))))) | F9: =IF(B9="","",SUMIFS(Purchase!$W$3:$W$1002,Purchase!$U$3:$U$1002,B9,Purchase!$C$3:$C$1002,C9)) | G9: =IF(OR(B9="",E9=""),"",E9-F9)
A10: =IF(COUNTA(B10:E10)=0,"",IF((IF(B10="","Vendor Invoice No, ","")&IF(C10="","Vendor, ","")&IF(D10="","Invoice Date, ","")&IF(E10="","Invoice Total, ",""))<>"","Missing: "&LEFT(IF(B10="","Vendor Invoice No, ","")&IF(C10="","Vendor, ","")&IF(D10="","Invoice Date, ","")&IF(E10="","Invoice Total, ",""),LEN(IF(B10="","Vendor Invoice No, ","")&IF(C10="","Vendor, ","")&IF(D10="","Invoice Date, ","")&IF(E10="","Invoice Total, ",""))-2),IF(COUNTIFS($B$3:$B$302,B10,$C$3:$C$302,C10)>1,"Bill "&B10&" is listed twice",IF(F10=0,"No Purchase row has this bill no for this vendor",IF(ABS(G10)>1,"Bill and rows differ by ₹"&TEXT(G10,"#,##0.00"),"OK"))))) | F10: =IF(B10="","",SUMIFS(Purchase!$W$3:$W$1002,Purchase!$U$3:$U$1002,B10,Purchase!$C$3:$C$1002,C10)) | G10: =IF(OR(B10="",E10=""),"",E10-F10)
A11: =IF(COUNTA(B11:E11)=0,"",IF((IF(B11="","Vendor Invoice No, ","")&IF(C11="","Vendor, ","")&IF(D11="","Invoice Date, ","")&IF(E11="","Invoice Total, ",""))<>"","Missing: "&LEFT(IF(B11="","Vendor Invoice No, ","")&IF(C11="","Vendor, ","")&IF(D11="","Invoice Date, ","")&IF(E11="","Invoice Total, ",""),LEN(IF(B11="","Vendor Invoice No, ","")&IF(C11="","Vendor, ","")&IF(D11="","Invoice Date, ","")&IF(E11="","Invoice Total, ",""))-2),IF(COUNTIFS($B$3:$B$302,B11,$C$3:$C$302,C11)>1,"Bill "&B11&" is listed twice",IF(F11=0,"No Purchase row has this bill no for this vendor",IF(ABS(G11)>1,"Bill and rows differ by ₹"&TEXT(G11,"#,##0.00"),"OK"))))) | F11: =IF(B11="","",SUMIFS(Purchase!$W$3:$W$1002,Purchase!$U$3:$U$1002,B11,Purchase!$C$3:$C$1002,C11)) | G11: =IF(OR(B11="",E11=""),"",E11-F11)
A12: =IF(COUNTA(B12:E12)=0,"",IF((IF(B12="","Vendor Invoice No, ","")&IF(C12="","Vendor, ","")&IF(D12="","Invoice Date, ","")&IF(E12="","Invoice Total, ",""))<>"","Missing: "&LEFT(IF(B12="","Vendor Invoice No, ","")&IF(C12="","Vendor, ","")&IF(D12="","Invoice Date, ","")&IF(E12="","Invoice Total, ",""),LEN(IF(B12="","Vendor Invoice No, ","")&IF(C12="","Vendor, ","")&IF(D12="","Invoice Date, ","")&IF(E12="","Invoice Total, ",""))-2),IF(COUNTIFS($B$3:$B$302,B12,$C$3:$C$302,C12)>1,"Bill "&B12&" is listed twice",IF(F12=0,"No Purchase row has this bill no for this vendor",IF(ABS(G12)>1,"Bill and rows differ by ₹"&TEXT(G12,"#,##0.00"),"OK"))))) | F12: =IF(B12="","",SUMIFS(Purchase!$W$3:$W$1002,Purchase!$U$3:$U$1002,B12,Purchase!$C$3:$C$1002,C12)) | G12: =IF(OR(B12="",E12=""),"",E12-F12)
A13: =IF(COUNTA(B13:E13)=0,"",IF((IF(B13="","Vendor Invoice No, ","")&IF(C13="","Vendor, ","")&IF(D13="","Invoice Date, ","")&IF(E13="","Invoice Total, ",""))<>"","Missing: "&LEFT(IF(B13="","Vendor Invoice No, ","")&IF(C13="","Vendor, ","")&IF(D13="","Invoice Date, ","")&IF(E13="","Invoice Total, ",""),LEN(IF(B13="","Vendor Invoice No, ","")&IF(C13="","Vendor, ","")&IF(D13="","Invoice Date, ","")&IF(E13="","Invoice Total, ",""))-2),IF(COUNTIFS($B$3:$B$302,B13,$C$3:$C$302,C13)>1,"Bill "&B13&" is listed twice",IF(F13=0,"No Purchase row has this bill no for this vendor",IF(ABS(G13)>1,"Bill and rows differ by ₹"&TEXT(G13,"#,##0.00"),"OK"))))) | F13: =IF(B13="","",SUMIFS(Purchase!$W$3:$W$1002,Purchase!$U$3:$U$1002,B13,Purchase!$C$3:$C$1002,C13)) | G13: =IF(OR(B13="",E13=""),"",E13-F13)
A14: =IF(COUNTA(B14:E14)=0,"",IF((IF(B14="","Vendor Invoice No, ","")&IF(C14="","Vendor, ","")&IF(D14="","Invoice Date, ","")&IF(E14="","Invoice Total, ",""))<>"","Missing: "&LEFT(IF(B14="","Vendor Invoice No, ","")&IF(C14="","Vendor, ","")&IF(D14="","Invoice Date, ","")&IF(E14="","Invoice Total, ",""),LEN(IF(B14="","Vendor Invoice No, ","")&IF(C14="","Vendor, ","")&IF(D14="","Invoice Date, ","")&IF(E14="","Invoice Total, ",""))-2),IF(COUNTIFS($B$3:$B$302,B14,$C$3:$C$302,C14)>1,"Bill "&B14&" is listed twice",IF(F14=0,"No Purchase row has this bill no for this vendor",IF(ABS(G14)>1,"Bill and rows differ by ₹"&TEXT(G14,"#,##0.00"),"OK"))))) | F14: =IF(B14="","",SUMIFS(Purchase!$W$3:$W$1002,Purchase!$U$3:$U$1002,B14,Purchase!$C$3:$C$1002,C14)) | G14: =IF(OR(B14="",E14=""),"",E14-F14)
... A302: =IF(COUNTA(B302:E302)=0,"",IF((IF(B302="","Vendor Invoice No, ","")&IF(C302="","Vendor, ","")&IF(D302="","Invoice Date, ","")&IF(E302="","Invoice Total, ",""))<>"","Missing: "&LEFT(IF(B302="","Vendor Invoice No, ","")&IF(C302="","Vendor, ","")&IF(D302="","Invoice Date, ","")&IF(E302="","Invoice Total, ",""),LEN(IF(B302="","Vendor Invoice No, ","")&IF(C302="","Vendor, ","")&IF(D302="","Invoice Date, ","")&IF(E302="","Invoice Total, ",""))-2),IF(COUNTIFS($B$3:$B$302,B302,$C$3:$C$302,C302)>1,"Bill "&B302&" is listed twice",IF(F302=0,"No Purchase row has this bill no for this vendor",IF(ABS(G302)>1,"Bill and rows differ by ₹"&TEXT(G302,"#,##0.00"),"OK"))))) | F302: =IF(B302="","",SUMIFS(Purchase!$W$3:$W$1002,Purchase!$U$3:$U$1002,B302,Purchase!$C$3:$C$1002,C302)) | G302: =IF(OR(B302="",E302=""),"",E302-F302)

Sheet Example
A1: Check | B1: PO Ref * | C1: Vendor * | D1: Store * | E1: Design No | F1: Product Type * | G1: Category * | H1: HSN Code * | I1: GST % | J1: Style | K1: Colour | L1: Polish | M1: Size | N1: Stone Type | O1: Stone Colour | P1: Photo | Q1: Qty * | R1: Purchase Rate (₹) * | S1: MRP (₹) * | T1: Amount (₹) | U1: Vendor Invoice No | V1: Received Qty | W1: Received Amount (₹) | Y1: Why this row looks like this
A2: # Automatic: says OK, or what to fix | B2: Required. Your name for this PO, e.g. SIY-OCT-01. Same PO Ref = one PO | C2: Required. Pick from the list (Vendors sheet) | D2: Required. Where the goods arrive | E2: Optional. Your label: same label = one design (1, 1, 1). Blank = own design | F2: Required. What it is: Earring, Necklace... | G2: Required. Collection: Antique, Kundan... | H2: Required. Pick from the list (see the Codes sheet) | I2: Auto, from the HSN | J2: Optional. Ball Drop, Cuff... | K2: Optional. Blank if it does not apply | L2: Optional | M2: Optional | N2: Optional | O2: Optional | P2: Optional. Photo file name(s), e.g. EI001-red.jpg, or a.jpg, b.jpg | Q2: Required. Pieces (a pair = 1) | R2: Required. Per piece, including GST, as on the bill | S2: Required. The price printed on the sticker | T2: Automatic: Qty × Rate | U2: When goods arrive: the bill no. Blank = PO only | V2: Only if it differs from Qty (short or extra) | W2: Automatic: received qty × rate
A3: =IF(COUNTA(B3:H3,J3:S3,U3:V3)=0,"",IF((IF(B3="","PO Ref, ","")&IF(C3="","Vendor, ","")&IF(D3="","Store, ","")&IF(F3="","Product Type, ","")&IF(G3="","Category, ","")&IF(H3="","HSN Code, ","")&IF(Q3="","Qty, ","")&IF(R3="","Purchase Rate, ","")&IF(S3="","MRP, ",""))<>"","Missing: "&LEFT(IF(B3="","PO Ref, ","")&IF(C3="","Vendor, ","")&IF(D3="","Store, ","")&IF(F3="","Product Type, ","")&IF(G3="","Category, ","")&IF(H3="","HSN Code, ","")&IF(Q3="","Qty, ","")&IF(R3="","Purchase Rate, ","")&IF(S3="","MRP, ",""),LEN(IF(B3="","PO Ref, ","")&IF(C3="","Vendor, ","")&IF(D3="","Store, ","")&IF(F3="","Product Type, ","")&IF(G3="","Category, ","")&IF(H3="","HSN Code, ","")&IF(Q3="","Qty, ","")&IF(R3="","Purchase Rate, ","")&IF(S3="","MRP, ",""))-2),IF(COUNTIF(Vendors!$B$3:$B$202,C3)=0,"Add vendor "&C3&" on the Vendors sheet",IF(ISNA(MATCH(H3,Codes!$A$2:$A$13,0)),"Pick the HSN Code from the list",IF(AND(E3<>"",COUNTIFS($C$3:$C$10,C3,$E$3:$E$10,E3,$F$3:$F$10,"<>"&F3)+COUNTIFS($C$3:$C$10,C3,$E$3:$E$10,E3,$G$3:$G$10,"<>"&G3)>0),"Design "&E3&" has another Product Type or Category on another row",IF(COUNTIFS($F$3:$F$10,F3,$G$3:$G$10,G3,$H$3:$H$10,"<>"&H3)>0,F3&" + "&G3&" has another HSN Code on another row",IF(AND(V3<>"",U3=""),"Received Qty needs the Vendor Invoice No",IF(AND(U3<>"",COUNTIFS($B$15:$B$15,U3,$C$15:$C$15,C3)=0),"Add bill "&U3&" of "&C3&" on the Bills sheet",IF(S3<R3,"MRP is below the Purchase Rate","OK"))))))))) -> OK | B3: SIY-OCT-01 | C3: Siyyona | D3: Main Store | E3: EI001 | F3: Earring | G3: Imported | H3: 7117 - Imitation / fashion jewellery | I3: =IF(H3="","",IFERROR(INDEX(Codes!$B$2:$B$13,MATCH(H3,Codes!$A$2:$A$13,0)),"")) -> 3 | J3: Huggie Hoop | K3: Purple | L3: Gold | M3: Free Size | N3: Glass | O3: Purple | P3: EI001-purple.jpg | Q3: 3 | R3: 90 | S3: 349 | T3: =IF(OR(Q3="",R3=""),"",Q3*R3) -> 270 | U3: SE/2526/PL/3568 | W3: =IF(OR(U3="",R3=""),"",IF(V3="",Q3,V3)*R3) -> 270 | Y3: Goods arrived: bill no filled, all 3 came. Its photo is EI001-purple.jpg
A4: =IF(COUNTA(B4:H4,J4:S4,U4:V4)=0,"",IF((IF(B4="","PO Ref, ","")&IF(C4="","Vendor, ","")&IF(D4="","Store, ","")&IF(F4="","Product Type, ","")&IF(G4="","Category, ","")&IF(H4="","HSN Code, ","")&IF(Q4="","Qty, ","")&IF(R4="","Purchase Rate, ","")&IF(S4="","MRP, ",""))<>"","Missing: "&LEFT(IF(B4="","PO Ref, ","")&IF(C4="","Vendor, ","")&IF(D4="","Store, ","")&IF(F4="","Product Type, ","")&IF(G4="","Category, ","")&IF(H4="","HSN Code, ","")&IF(Q4="","Qty, ","")&IF(R4="","Purchase Rate, ","")&IF(S4="","MRP, ",""),LEN(IF(B4="","PO Ref, ","")&IF(C4="","Vendor, ","")&IF(D4="","Store, ","")&IF(F4="","Product Type, ","")&IF(G4="","Category, ","")&IF(H4="","HSN Code, ","")&IF(Q4="","Qty, ","")&IF(R4="","Purchase Rate, ","")&IF(S4="","MRP, ",""))-2),IF(COUNTIF(Vendors!$B$3:$B$202,C4)=0,"Add vendor "&C4&" on the Vendors sheet",IF(ISNA(MATCH(H4,Codes!$A$2:$A$13,0)),"Pick the HSN Code from the list",IF(AND(E4<>"",COUNTIFS($C$3:$C$10,C4,$E$3:$E$10,E4,$F$3:$F$10,"<>"&F4)+COUNTIFS($C$3:$C$10,C4,$E$3:$E$10,E4,$G$3:$G$10,"<>"&G4)>0),"Design "&E4&" has another Product Type or Category on another row",IF(COUNTIFS($F$3:$F$10,F4,$G$3:$G$10,G4,$H$3:$H$10,"<>"&H4)>0,F4&" + "&G4&" has another HSN Code on another row",IF(AND(V4<>"",U4=""),"Received Qty needs the Vendor Invoice No",IF(AND(U4<>"",COUNTIFS($B$15:$B$15,U4,$C$15:$C$15,C4)=0),"Add bill "&U4&" of "&C4&" on the Bills sheet",IF(S4<R4,"MRP is below the Purchase Rate","OK"))))))))) -> OK | B4: SIY-OCT-01 | C4: Siyyona | D4: Main Store | E4: EI001 | F4: Earring | G4: Imported | H4: 7117 - Imitation / fashion jewellery | I4: =IF(H4="","",IFERROR(INDEX(Codes!$B$2:$B$13,MATCH(H4,Codes!$A$2:$A$13,0)),"")) -> 3 | J4: Huggie Hoop | K4: White | L4: Rose Gold | M4: Free Size | N4: Glass | O4: White | P4: EI001-white.jpg, EI001-white-back.jpg | Q4: 3 | R4: 90 | S4: 349 | T4: =IF(OR(Q4="",R4=""),"",Q4*R4) -> 270 | U4: SE/2526/PL/3568 | W4: =IF(OR(U4="",R4=""),"",IF(V4="",Q4,V4)*R4) -> 270 | Y4: Same design EI001 in another colour = a new row. Two photos
A5: =IF(COUNTA(B5:H5,J5:S5,U5:V5)=0,"",IF((IF(B5="","PO Ref, ","")&IF(C5="","Vendor, ","")&IF(D5="","Store, ","")&IF(F5="","Product Type, ","")&IF(G5="","Category, ","")&IF(H5="","HSN Code, ","")&IF(Q5="","Qty, ","")&IF(R5="","Purchase Rate, ","")&IF(S5="","MRP, ",""))<>"","Missing: "&LEFT(IF(B5="","PO Ref, ","")&IF(C5="","Vendor, ","")&IF(D5="","Store, ","")&IF(F5="","Product Type, ","")&IF(G5="","Category, ","")&IF(H5="","HSN Code, ","")&IF(Q5="","Qty, ","")&IF(R5="","Purchase Rate, ","")&IF(S5="","MRP, ",""),LEN(IF(B5="","PO Ref, ","")&IF(C5="","Vendor, ","")&IF(D5="","Store, ","")&IF(F5="","Product Type, ","")&IF(G5="","Category, ","")&IF(H5="","HSN Code, ","")&IF(Q5="","Qty, ","")&IF(R5="","Purchase Rate, ","")&IF(S5="","MRP, ",""))-2),IF(COUNTIF(Vendors!$B$3:$B$202,C5)=0,"Add vendor "&C5&" on the Vendors sheet",IF(ISNA(MATCH(H5,Codes!$A$2:$A$13,0)),"Pick the HSN Code from the list",IF(AND(E5<>"",COUNTIFS($C$3:$C$10,C5,$E$3:$E$10,E5,$F$3:$F$10,"<>"&F5)+COUNTIFS($C$3:$C$10,C5,$E$3:$E$10,E5,$G$3:$G$10,"<>"&G5)>0),"Design "&E5&" has another Product Type or Category on another row",IF(COUNTIFS($F$3:$F$10,F5,$G$3:$G$10,G5,$H$3:$H$10,"<>"&H5)>0,F5&" + "&G5&" has another HSN Code on another row",IF(AND(V5<>"",U5=""),"Received Qty needs the Vendor Invoice No",IF(AND(U5<>"",COUNTIFS($B$15:$B$15,U5,$C$15:$C$15,C5)=0),"Add bill "&U5&" of "&C5&" on the Bills sheet",IF(S5<R5,"MRP is below the Purchase Rate","OK"))))))))) -> OK | B5: SIY-OCT-01 | C5: Siyyona | D5: Main Store | E5: EI002 | F5: Earring | G5: Imported | H5: 7117 - Imitation / fashion jewellery | I5: =IF(H5="","",IFERROR(INDEX(Codes!$B$2:$B$13,MATCH(H5,Codes!$A$2:$A$13,0)),"")) -> 3 | J5: Ball Drop | K5: White | L5: Gold | M5: Free Size | Q5: 3 | R5: 90 | S5: 325 | T5: =IF(OR(Q5="",R5=""),"",Q5*R5) -> 270 | U5: SE/2526/PL/3568 | V5: 2 | W5: =IF(OR(U5="",R5=""),"",IF(V5="",Q5,V5)*R5) -> 180 | Y5: Only 2 of 3 came: Received Qty = 2
